Workbook

Sheet INFO
A1: Combat (CBT) | C1: Team (TM) | F1: CPLT | H1: TM A | I1: =SUM(I2:I3) -> 4
A2: Infantry | C2: Squad (SQD) | F2: SGT | H2: TM LDR | I2: 1
A3: Cavalry | C3: Platoon (PLT) | F3: 2LT | H3: 3x PAX | I3: 3
A4: Artillery | C4: Company (CO) | D4: Troop (TRP) | E4: Battery (BTRY) | F4: CPT | H4: SQD A | I4: =SUM(I5:I6) -> 13
A5: Combat Support | C5: Battalion (BN) | D5: Squadron (SQ) | F5: LTC | H5: SQD LDR | I5: 1
A6: AMD | C6: Brigade (BDE) | D6: Regiment (REGT) | F6: COL | H6: 3x TM | I6: =I1*3 -> 12
A7: Engineers | C7: Division (DIV) | F7: MG | H7: PLT A | I7: =SUM(I8:I11) -> 54
A8: CBRNE | C8: Corps (CORPS) | F8: LTG | H8: PLT LDR | I8: 1
A9: MP | C9: Army (ARMY) | F9: GEN | H9: PLT SGT | I9: 1
A10: CA | H10: HQ SQD | I10: =I4 -> 13
A11: PSYOPS | H11: 3x SQD | I11: =I4*3 -> 39
A12: Sustainment | H12: CO A | I12: =SUM(I13:I17) -> 219
A13: Supply | H13: CO CDR | I13: 1
A14: Maintenance | H14: CO XO | I14: 1
A15: Medical | H15: CO 1SG | I15: 1
A16: Transportation | H16: HQ PLT | I16: =I7 -> 54
A17: Field Services | H17: 3x PLT | I17: =I7*3 -> 162
A18: ISR | H18: BN A | I18: =SUM(I19:I24) -> 1098
A19: Reconnaissance | H19: BN CDR | I19: 1
A20: SIGINT/ELINT | H20: BN XO | I20: 1
A21: HUMINT | H21: BN CSM | I21: 1
A22: MASINT | H22: BN HQ CO | I22: =I12 -> 219
A23: ISR-UAV | H23: 3x CO | I23: =I12*3 -> 657
A24: C4I | H24: SPT CO | I24: =I12 -> 219
A25: Command | H25: BDE A | I25: =SUM(I26:I31) -> 5493
A26: Staff | H26: BDE CDR | I26: 1
A27: Command Post | H27: BDE DCO | I27: 1
A28: Commo and IS | H28: BDE CSM | I28: 1
A29: Administration | H29: HQ BN | I29: =I18 -> 1098
H30: 3x BN | I30: =I18*3 -> 3294
H31: SPT BN | I31: =I18 -> 1098
H32: DIV A | I32: =SUM(I33:I37) -> 17580
H33: DIV CG | I33: 1
H34: DIV DCG | I34: 1
H35: DIV CSM | I35: 1
H36: DSTB | I36: =I18 -> 1098
H37: 3x BDE | I37: =I25*3 -> 16479
H38: CORPS A | I38: =SUM(I39:I43) -> 53721
H39: CORPS CG | I39: 1
H40: CORPS DCG | I40: 1
...

Sheet PLT(-)
A1: PLT A | B1: =E1 -> 54 | D1: PLT A | E1: =SUM(E2:E5) -> 54
A2: HQ PLT A | B2: =E7 -> 52 | D2: PLT LDR | E2: 1
A3: INF PLT A | B3: =E13 -> 65 | D3: PLT SGT | E3: 1
A4: INF WPNS PLT A | B4: =E18 -> 39 | D4: HQ SQD | E4: =INFO!I4 -> 13
A5: SPT PLT A | B5: =E23 -> 104 | D5: 3x SQD | E5: =INFO!I4*3 -> 39
D7: HQ PLT A | E7: =SUM(E8:E11) -> 52
D8: CMD SQD | E8: =INFO!I4 -> 13
D9: STAFF SQD | E9: =INFO!I4 -> 13
D10: CP SQD | E10: =INFO!I4 -> 13
D11: ISR SQD | E11: =INFO!I4 -> 13
D13: INF PLT A | E13: =SUM(E14:E16) -> 65
D14: HQ SQD | E14: =INFO!I4 -> 13
D15: WPNS SQD | E15: =INFO!I4 -> 13
D16: 3x INF SQD | E16: =INFO!I4*3 -> 39
D18: INF WPNS PLT A | E18: =SUM(E19:E21) -> 39
D19: HQ SQD | E19: =INFO!I4 -> 13
D20: MSL SQD | E20: =INFO!I4 -> 13
D21: MORT SQD | E21: =INFO!I4 -> 13
D23: SPT PLT A | E23: =SUM(E24:E31) -> 104
D24: HQ SQD | E24: =INFO!I4 -> 13
D25: SPLY SQD | E25: =INFO!I4 -> 13
D26: MAINT SQD | E26: =INFO!I4 -> 13
D27: MED SQD | E27: =INFO!I4 -> 13
D28: ENG SQD | E28: =INFO!I4 -> 13
D29: AMD SQD | E29: =INFO!I4 -> 13
D30: CBRNE SQD | E30: =INFO!I4 -> 13
D31: MP SQD | E31: =INFO!I4 -> 13
E1048576: =INFO!I1048561 -> 0

Sheet CO
A1: CO A | B1: =E1 -> 273 | D1: CO A | E1: =SUM(E2:E7) -> 273
A2: HQ CO A | B2: =E9 -> 270 | D2: CO CDR | E2: 1
A3: ISR CO A | B3: =E18 -> 324 | D3: CO XO | E3: 1
A4: INF CO A | B4: =E26 -> 270 | D4: CO 1SG | E4: 1
A5: FA BTRY A | B5: =E38 -> 108 | D5: HQ PLT | E5: =INFO!I7 -> 54
A6: CS CO A | B6: =E45 -> 378 | D6: 3x PLT | E6: =INFO!I7*3 -> 162
A7: SUS CO A | B7: =E54 -> 270 | D7: SPT PLT | E7: =INFO!I7 -> 54
A8: SIG CO A | B8: =E61 -> 216
A9: SPT CO A | B9: =E67 -> 432 | D9: HQ CO A | E9: =SUM(E10:E14) -> 270 | G9: HQ CO B | H9: =SUM(H10:H16) -> 378
A10: SPLY CO A | B10: =E77 -> 324 | D10: CMD PLT | E10: =INFO!I7 -> 54 | G10: CMD PLT | H10: ='PLT(-)'!B1 -> 54
A11: MAINT CO A | B11: =E85 -> 162 | D11: STAFF PLT | E11: =INFO!I7 -> 54 | G11: STAFF PLT | H11: ='PLT(-)'!B1 -> 54
A12: MED CO A | B12: =E90 -> 270 | D12: ADMIN PLT | E12: =INFO!I7 -> 54 | G12: ADMIN PLT | H12: ='PLT(-)'!B1 -> 54
A13: FLD SPT CO A | B13: =E97 -> 378 | D13: COMMO PLT | E13: =INFO!I7 -> 54 | G13: COMMO PLT | H13: ='PLT(-)'!B1 -> 54
A14: ENG CO A | B14: =E106 -> 324 | D14: BN CP PLT | E14: =INFO!I7 -> 54 | G14: BN CP PLT | H14: ='PLT(-)'!B1 -> 54
A15: AMD BTRY A | B15: =E114 -> 270 | G15: ISR PLT | H15: ='PLT(-)'!B1 -> 54
A16: CBRNE CO A | B16: =E121 -> 162 | G16: SPT PLT | H16: ='PLT(-)'!B1 -> 54
A17: MP CO A | B17: =E126 -> 270
A18: CA CO A | B18: =E133 -> 108 | D18: ISR CO A | E18: =SUM(E19:E24) -> 324
A19: PSYOPS CO A | B19: =E137 -> 108 | D19: HQ PLT | E19: =INFO!I7 -> 54
A20: RECON CO A | B20: =E141 -> 216 | D20: RECON PLT | E20: =INFO!I7 -> 54
A21: HUMINT CO A | B21: =E145 -> 216 | D21: HUMINT PLT | E21: =INFO!I7 -> 54
A22: SIGINT CO A | B22: =E149 -> 216 | D22: SIGINT PLT | E22: =INFO!I7 -> 54
A23: MASINT CO A | B23: =E153 -> 216 | D23: ISR-UAV PLT | E23: =INFO!I7 -> 54
A24: UAV CO A | B24: =E157 -> 270 | D24: MASINT PLT | E24: =INFO!I7 -> 54
A25: CAV TRP A | B25: =E32 -> 216
A26: INF CO B | B26: =H26 -> 390 | D26: INF CO A | E26: =SUM(E27:E29) -> 270 | G26: INF CO B | H26: =SUM(H27:H30) -> 390
A27: HQ CO B | B27: =H9 -> 378 | D27: INF CO HQ PLT | E27: =INFO!I7 -> 54 | G27: HQ PLT | H27: ='PLT(-)'!B2 -> 52
A28: CAV TRP B | B28: =H32 -> 324 | D28: 3x INF PLT | E28: =INFO!I7*3 -> 162 | G28: 3x INF PLT | H28: ='PLT(-)'!B3*3 -> 195
A29: FA BTRY B | B29: =H38 -> 270 | D29: WPNS PLT | E29: =INFO!I7 -> 54 | G29: WPNS PLT | H29: ='PLT(-)'!B4 -> 39
G30: SPT PLT | H30: ='PLT(-)'!E23 -> 104
D32: CAV TRP A | E32: =SUM(E33:E34) -> 216 | G32: CAV TRP B | H32: =SUM(H33:H36) -> 324
D33: CAV TRP HQ PLT | E33: =INFO!I7 -> 54 | G33: CAV TRP HQ PLT | H33: ='PLT(-)'!B1 -> 54
D34: 3x CAV PLT | E34: =INFO!I7*3 -> 162 | G34: 3x CAV PLT | H34: ='PLT(-)'!B1*3 -> 162
G35: A-UGV PLT | H35: ='PLT(-)'!B1 -> 54
G36: SPT PLT | H36: ='PLT(-)'!B1 -> 54
D38: FA BTRY A | E38: =SUM(E39:E40) -> 108 | G38: FA BTRY B | H38: =SUM(H39:H43) -> 270
D39: HQ PLT | E39: =INFO!I7 -> 54 | G39: HQ PLT | H39: ='PLT(-)'!B1 -> 54
D40: IDF PLT | E40: =INFO!I7 -> 54 | G40: IDF PLT | H40: ='PLT(-)'!B1 -> 54
G41: AMD PLT | H41: ='PLT(-)'!B1 -> 54
G42: SPT PLT | H42: ='PLT(-)'!B1 -> 54
...

Sheet BN
A1: BN A | B1: =E1 -> 978 | D1: BN A | E1: =SUM(E2:E7) -> 978
A2: HQ BN A | B2: =E18 -> 648 | D2: BN CDR | E2: 1
A3: S BN A | B3: =E25 -> 1095 | D3: BN XO | E3: 1
A4: CS BN A | B4: =E38 -> 1242 | D4: BN CSM | E4: 1
A5: ISR BN A | B5: =E47 -> 1134 | D5: HQ CO A | E5: =CO!B2 -> 270
A6: CBT BN A | B6: =E9 -> 2106 | D6: 3x CO | E6: =CO!B1 -> 273
A7: CBT BN B | B7: =H9 -> 2574 | D7: SPT CO | E7: =CO!B9 -> 432
A8: HQ BN B | B8: =H18 -> 1512
A9: SPT BN B | B9: =H25 -> 2646 | D9: CBN A | E9: =SUM(E10:E16) -> 2106 | G9: CBT BN B | H9: =SUM(H10:H14) -> 2574
D10: BN HQ CO A | E10: =INFO!O10 -> 0 | G10: HQ CO B | H10: =CO!H9 -> 378
D11: 3x INF CO | E11: =CO!E26*3 -> 810 | G11: 3x INF CO B | H11: =CO!B26*3 -> 1170
D12: CAV TRP | E12: =CO!E32 -> 216 | G12: CAV TRP B | H12: =CO!B28 -> 324
D13: FA BTRY | E13: =CO!E38 -> 108 | G13: FA BTRY A | H13: =CO!B29 -> 270
D14: ISR CO | E14: =CO!E18 -> 324 | G14: SPT CO A | H14: =CO!B9 -> 432
D15: CS CO | E15: =CO!E45 -> 378
D16: SUS CO | E16: =CO!E54 -> 270
D18: HQ BN A | E18: =SUM(E19:E22) -> 648 | G18: HQ BN B | H18: =SUM(H19:H23) -> 1512
D19: HQ CO A (BN HQ) | E19: =INFO!O10 -> 0 | G19: HQ CO A (BN) | H19: =CO!B2 -> 270
D20: HQ CO A (BDE HQ) | E20: =INFO!O10 -> 0 | G20: HQ CO A (BDE) | H20: =CO!B2 -> 270
D21: SIG CO A (BDE SIG) | E21: =CO!E61 -> 216 | G21: ISR CO | H21: =CO!B3 -> 324
D22: SPT CO A (BN SPT) | E22: =CO!E67 -> 432 | G22: SIG CO | H22: =CO!B8 -> 216
G23: SPT CO | H23: =CO!B9 -> 432
D25: SBN A | E25: 1095 | G25: SPT BN B | H25: =SUM(H26:H36) -> 2646
D26: BN HQ CO A | E26: =INFO!O10 -> 0 | G26: HQ CO A | H26: =CO!B2 -> 270
D27: SPLY CO A | E27: =CO!E77 -> 324 | G27: SPLY CO A | H27: =CO!B10 -> 324
D28: MAINT CO A | E28: =CO!E85 -> 162 | G28: MAINT CO A | H28: =CO!B11 -> 162
D29: MED CO A | E29: =CO!E90 -> 270 | G29: MED CO A | H29: =CO!B12 -> 270
D30: FLD SPT CO A | E30: =CO!E97 -> 378 | G30: FLD SPT CO A | H30: =CO!B13 -> 378
G31: ENG CO A | H31: =CO!B14 -> 324
G32: AMD BTRY A | H32: =CO!B15 -> 270
G33: CBRNE CO A | H33: =CO!B16 -> 162
G34: MP CO A | H34: =CO!B17 -> 270
G35: CA CO A | H35: =CO!B18 -> 108
G36: PSYOPS CO A | H36: =CO!B19 -> 108
D38: CSBN A | E38: =SUM(E39:E45) -> 1242
D39: HQ CO A (BN HQ) | E39: =INFO!O10 -> 0
D40: ENG CO A | E40: =CO!E106 -> 324
D41: AMD CO A | E41: =CO!E114 -> 270
D42: CBRNE CO A | E42: =CO!E121 -> 162
D43: MP CO A | E43: =CO!E126 -> 270
...

Sheet BDE
A1: BDE A | B1: =E1 -> 4680 | D1: BDE A | E1: =SUM(E2:E7) -> 4680
A2: CBT BDE A | B2: =E9 -> 10887 | D2: BDE CDR | E2: 1
A3: CBT BDE B | B3: =E16 -> 11880 | D3: BDE DCO | E3: 1
D4: BDE CSM | E4: 1
D5: HQ BN | E5: =BN!B2 -> 648
D6: 3x BN | E6: =BN!B1*3 -> 2934
D7: SPT BN | E7: =BN!B3 -> 1095
D9: CBT BDE A | E9: =SUM(E10:E14) -> 10887
D10: HQ BN | E10: =INFO!I18 -> 1098
D11: 3x CBN | E11: =BN!B6*3 -> 6318
D12: CSBN | E12: =BN!B4 -> 1242
D13: ISR BN A | E13: =BN!B5 -> 1134
D14: SBN | E14: =BN!B3 -> 1095
D16: CBT BDE B | E16: =SUM(E17:E19) -> 11880
D17: HQ BN B | E17: =BN!H18 -> 1512
D18: 3x CBT BN B | E18: =BN!H9*3 -> 7722
D19: SPT BN B | E19: =BN!H25 -> 2646
